Workbook
Name Slicer_Source___Medium: #N/A
Name Timeline_Date: #N/A
Name web_analytics: 'Web Analytic_Dataset'!$A$1:$U$247

Sheet Web Analytic_Dataset
A1: Source / Medium | B1: Year | C1: Date | D1: Month of the year | E1: Users | F1: New Users | G1: Returning Users | H1: Sessions | I1: Bounce Rate | J1: Pageviews | K1: Avg. Session Duration | L1: Avg PageViews/Session | M1: Conversion Rate (%) | N1: Transactions | O1: Revenue | P1: Quantity Sold | Q1: User Retention Rate % | R1: Revenue Per User | S1: Revenue Per Session | T1: Revenue Per Transactions | U1: Cost Per Conversion % | V1: Average Conversion Rate in 2020 | W1: Average Conversion rate 2019
A2: A | B2: 2019 | C2: =DATE(B2,D2,1) -> 43770 | D2: 11 | E2: 126870 | F2: 104020 | G2: =E2-F2 -> 22850 | H2: 194667 | I2: 0.7159 | J2: 455159 | K2: 0.00082175926 | L2: =J2/H2 -> 2.3381415 | M2: 0.2 | N2: 394 | O2: 83244 | P2: 482 | Q2: =(G2/E2)*100 -> 18.010562 | R2: =O2/E2 -> 0.6561362 | S2: =O2/H2 -> 0.42762256 | T2: =O2/N2 -> 211.27919 | U2: =1/M2 -> 5 | V2: =AVERAGEIF($B$2:$B$247,2020,$M$2:$M$247) -> 3.303121 | W2: =AVERAGEIF($B$2:$B$247,2019,$M$2:$M$247) -> 2.9876404
A3: A | B3: 2020 | C3: =DATE(B3,D3,1) -> 43952 | D3: 5 | E3: 120625 | F3: 98574 | G3: =E3-F3 -> 22051 | H3: 194114 | I3: 0.6456 | J3: 559509 | K3: 0.0010648148 | L3: =J3/H3 -> 2.8823732 | M3: 0.69 | N3: 1347 | O3: 203552 | P3: 2402 | Q3: =(G3/E3)*100 -> 18.280622 | R3: =O3/E3 -> 1.6874777 | S3: =O3/H3 -> 1.0486209 | T3: =O3/N3 -> 151.11507 | U3: =1/M3 -> 1.4492754
A4: A | B4: 2019 | C4: =DATE(B4,D4,1) -> 43739 | D4: 10 | E4: 123361 | F4: 104308 | G4: =E4-F4 -> 19053 | H4: 181175 | I4: 0.4191 | J4: 368907 | K4: 0.00075231481 | L4: =J4/H4 -> 2.0361915 | M4: 0.26 | N4: 477 | O4: 94282 | P4: 599 | Q4: =(G4/E4)*100 -> 15.444914 | R4: =O4/E4 -> 0.7642772 | S4: =O4/H4 -> 0.52039189 | T4: =O4/N4 -> 197.65618 | U4: =1/M4 -> 3.8461538
A5: A | B5: 2019 | C5: =DATE(B5,D5,1) -> 43709 | D5: 9 | E5: 106551 | F5: 88428 | G5: =E5-F5 -> 18123 | H5: 170329 | I5: 0.7592 | J5: 368803 | K5: 0.00070601852 | L5: =J5/H5 -> 2.165239 | M5: 0.18 | N5: 311 | O5: 54971 | P5: 415 | Q5: =(G5/E5)*100 -> 17.008756 | R5: =O5/E5 -> 0.51591257 | S5: =O5/H5 -> 0.32273424 | T5: =O5/N5 -> 176.75563 | U5: =1/M5 -> 5.5555556
A6: A | B6: 2020 | C6: =DATE(B6,D6,1) -> 43983 | D6: 6 | E6: 102123 | F6: 82461 | G6: =E6-F6 -> 19662 | H6: 163446 | I6: 0.671 | J6: 425410 | K6: 0.00092592593 | L6: =J6/H6 -> 2.6027557 | M6: 0.7 | N6: 1138 | O6: 167113 | P6: 1987 | Q6: =(G6/E6)*100 -> 19.253253 | R6: =O6/E6 -> 1.6363895 | S6: =O6/H6 -> 1.0224355 | T6: =O6/N6 -> 146.84798 | U6: =1/M6 -> 1.4285714
A7: A | B7: 2019 | C7: =DATE(B7,D7,1) -> 43800 | D7: 12 | E7: 91043 | F7: 70326 | G7: =E7-F7 -> 20717 | H7: 142637 | I7: 0.6706 | J7: 370798 | K7: 0.00092592593 | L7: =J7/H7 -> 2.599592 | M7: 0.34 | N7: 486 | O7: 103001 | P7: 607 | Q7: =(G7/E7)*100 -> 22.755182 | R7: =O7/E7 -> 1.1313445 | S7: =O7/H7 -> 0.72211979 | T7: =O7/N7 -> 211.93621 | U7: =1/M7 -> 2.9411765
A8: A | B8: 2020 | C8: =DATE(B8,D8,1) -> 43831 | D8: 1 | E8: 83031 | F8: 64103 | G8: =E8-F8 -> 18928 | H8: 133736 | I8: 0.6946 | J8: 373356 | K8: 0.00096064815 | L8: =J8/H8 -> 2.7917389 | M8: 0.45 | N8: 601 | O8: 128552 | P8: 777 | Q8: =(G8/E8)*100 -> 22.796305 | R8: =O8/E8 -> 1.548241 | S8: =O8/H8 -> 0.96123706 | T8: =O8/N8 -> 213.89684 | U8: =1/M8 -> 2.2222222
A9: A | B9: 2020 | C9: =DATE(B9,D9,1) -> 44013 | D9: 7 | E9: 84343 | F9: 73239 | G9: =E9-F9 -> 11104 | H9: 125423 | I9: 0.7116 | J9: 292263 | K9: 0.00083333333 | L9: =J9/H9 -> 2.3302185 | M9: 0.58 | N9: 730 | O9: 98161 | P9: 1360 | Q9: =(G9/E9)*100 -> 13.165289 | R9: =O9/E9 -> 1.163831 | S9: =O9/H9 -> 0.78263955 | T9: =O9/N9 -> 134.46712 | U9: =1/M9 -> 1.7241379
A10: A | B10: 2020 | C10: =DATE(B10,D10,1) -> 43862 | D10: 2 | E10: 82626 | F10: 68145 | G10: =E10-F10 -> 14481 | H10: 125318 | I10: 0.7006 | J10: 328822 | K10: 0.00097222222 | L10: =J10/H10 -> 2.6239008 | M10: 0.52 | N10: 657 | O10: 126137 | P10: 981 | Q10: =(G10/E10)*100 -> 17.52596 | R10: =O10/E10 -> 1.5266018 | S10: =O10/H10 -> 1.0065354 | T10: =O10/N10 -> 191.98935 | U10: =1/M10 -> 1.9230769
A11: A | B11: 2020 | C11: =DATE(B11,D11,1) -> 43891 | D11: 3 | E11: 73844 | F11: 61557 | G11: =E11-F11 -> 12287 | H11: 110546 | I11: 0.7219 | J11: 266187 | K11: 0.00086805556 | L11: =J11/H11 -> 2.4079297 | M11: 0.48 | N11: 531 | O11: 96195 | P11: 843 | Q11: =(G11/E11)*100 -> 16.639131 | R11: =O11/E11 -> 1.3026786 | S11: =O11/H11 -> 0.87018074 | T11: =O11/N11 -> 181.15819 | U11: =1/M11 -> 2.0833333
A12: B | B12: 2019 | C12: =DATE(B12,D12,1) -> 43800 | D12: 12 | E12: 88579 | F12: 75361 | G12: =E12-F12 -> 13218 | H12: 106966 | I12: 0.562 | J12: 333480 | K12: 0.0013310185 | L12: =J12/H12 -> 3.1176262 | M12: 0.21 | N12: 225 | O12: 47724 | P12: 317 | Q12: =(G12/E12)*100 -> 14.922273 | R12: =O12/E12 -> 0.5387733 | S12: =O12/H12 -> 0.44616046 | T12: =O12/N12 -> 212.10667 | U12: =1/M12 -> 4.7619048
A13: A | B13: 2020 | C13: =DATE(B13,D13,1) -> 43922 | D13: 4 | E13: 73349 | F13: 62794 | G13: =E13-F13 -> 10555 | H13: 104146 | I13: 0.6712 | J13: 288195 | K13: 0.0009837963 | L13: =J13/H13 -> 2.767221 | M13: 0.6 | N13: 622 | O13: 95367 | P13: 1150 | Q13: =(G13/E13)*100 -> 14.390108 | R13: =O13/E13 -> 1.3001813 | S13: =O13/H13 -> 0.91570488 | T13: =O13/N13 -> 153.32315 | U13: =1/M13 -> 1.6666667
A14: C | B14: 2020 | C14: =DATE(B14,D14,1) -> 43952 | D14: 5 | E14: 68869 | F14: 55769 | G14: =E14-F14 -> 13100 | H14: 99838 | I14: 0.5098 | J14: 325311 | K14: 0.0011342593 | L14: =J14/H14 -> 3.2583886 | M14: 0.47 | N14: 471 | O14: 58744 | P14: 819 | Q14: =(G14/E14)*100 -> 19.021621 | R14: =O14/E14 -> 0.85298175 | S14: =O14/H14 -> 0.5883932 | T14: =O14/N14 -> 124.72187 | U14: =1/M14 -> 2.1276596
... A75: M | B75: 2019 | C75: =DATE(B75,D75,1) -> 43709 | D75: 9 | E75: 3504 | F75: 2184 | G75: =E75-F75 -> 1320 | H75: 4882 | I75: 0.5647 | J75: 16125 | K75: 0.0013773148 | L75: =J75/H75 -> 3.3029496 | M75: 0.2 | N75: 10 | O75: 1576 | P75: 17 | Q75: =(G75/E75)*100 -> 37.671233 | R75: =O75/E75 -> 0.44977169 | S75: =O75/H75 -> 0.32281852 | T75: =O75/N75 -> 157.6 | U75: =1/M75 -> 5
A76: N | B76: 2020 | C76: =DATE(B76,D76,1) -> 43952 | D76: 5 | E76: 4224 | F76: 4151 | G76: =E76-F76 -> 73 | H76: 4822 | I76: 0.8281 | J76: 7727 | K76: 0.00048611111 | L76: =J76/H76 -> 1.6024471 | M76: 0 | N76: 0 | O76: 0 | P76: 0 | Q76: =(G76/E76)*100 -> 1.7282197 | R76: =O76/E76 -> 0 | S76: =O76/H76 -> 0 | T76: =O76/N76 -> #DIV/0! | U76: =1/M76 -> #DIV/0! | V76: =SUMIF(B76:B321,2019,F76:F321) -> 27099 | W76: =AVERAGEIF($B$2:$B$247,2019,$M$2:$M$247) -> 2.9876404
A77: M | B77: 2019 | C77: =DATE(B77,D77,1) -> 43739 | D77: 10 | E77: 2824 | F77: 1701 | G77: =E77-F77 -> 1123 | H77: 4150 | I77: 0.2976 | J77: 15145 | K77: 0.0015509259 | L77: =J77/H77 -> 3.6493976 | M77: 0.14 | N77: 6 | O77: 1217 | P77: 14 | Q77: =(G77/E77)*100 -> 39.766289 | R77: =O77/E77 -> 0.43094901 | S77: =O77/H77 -> 0.29325301 | T77: =O77/N77 -> 202.83333 | U77: =1/M77 -> 7.1428571
A78: L | B78: 2019 | C78: =DATE(B78,D78,1) -> 43770 | D78: 11 | E78: 1830 | F78: 31 | G78: =E78-F78 -> 1799 | H78: 4060 | I78: 0.7916 | J78: 8122 | K78: 0.00085648148 | L78: =J78/H78 -> 2.0004926 | M78: 0.12 | N78: 5 | O78: 623 | P78: 9 | Q78: =(G78/E78)*100 -> 98.306011 | R78: =O78/E78 -> 0.34043716 | S78: =O78/H78 -> 0.15344828 | T78: =O78/N78 -> 124.6 | U78: =1/M78 -> 8.3333333
A79: L | B79: 2019 | C79: =DATE(B79,D79,1) -> 43800 | D79: 12 | E79: 1890 | F79: 18 | G79: =E79-F79 -> 1872 | H79: 4033 | I79: 0.7295 | J79: 10040 | K79: 0.0014236111 | L79: =J79/H79 -> 2.4894619 | M79: 0.17 | N79: 7 | O79: 1320 | P79: 12 | Q79: =(G79/E79)*100 -> 99.047619 | R79: =O79/E79 -> 0.6984127 | S79: =O79/H79 -> 0.32729978 | T79: =O79/N79 -> 188.57143 | U79: =1/M79 -> 5.8823529
A80: K | B80: 2019 | C80: =DATE(B80,D80,1) -> 43709 | D80: 9 | E80: 3345 | F80: 3031 | G80: =E80-F80 -> 314 | H80: 3721 | I80: 0.5028 | J80: 11704 | K80: 0.00087962963 | L80: =J80/H80 -> 3.145391 | M80: 0 | N80: 0 | O80: 0 | P80: 0 | Q80: =(G80/E80)*100 -> 9.387145 | R80: =O80/E80 -> 0 | S80: =O80/H80 -> 0 | T80: =O80/N80 -> #DIV/0! | U80: =1/M80 -> #DIV/0! | V80: =SUMIF(B80:B325,2019,F80:F325) -> 25349 | W80: =AVERAGEIF($B$2:$B$247,2019,$M$2:$M$247) -> 2.9876404
A81: O | B81: 2020 | C81: =DATE(B81,D81,1) -> 43983 | D81: 6 | E81: 1422 | F81: 20 | G81: =E81-F81 -> 1402 | H81: 3714 | I81: 0.7571 | J81: 7597 | K81: 0.0010763889 | L81: =J81/H81 -> 2.0455035 | M81: 0.03 | N81: 1 | O81: 111 | P81: 5 | Q81: =(G81/E81)*100 -> 98.59353 | R81: =O81/E81 -> 0.078059072 | S81: =O81/H81 -> 0.029886914 | T81: =O81/N81 -> 111 | U81: =1/M81 -> 33.333333
A82: L | B82: 2019 | C82: =DATE(B82,D82,1) -> 43739 | D82: 10 | E82: 1528 | F82: 11 | G82: =E82-F82 -> 1517 | H82: 3703 | I82: 0.5514 | J82: 7678 | K82: 0.00087962963 | L82: =J82/H82 -> 2.073454 | M82: 0 | N82: 0 | O82: 0 | P82: 0 | Q82: =(G82/E82)*100 -> 99.280105 | R82: =O82/E82 -> 0 | S82: =O82/H82 -> 0 | T82: =O82/N82 -> #DIV/0! | U82: =1/M82 -> #DIV/0! | V82: =SUMIF(B82:B327,2019,F82:F327) -> 22318 | W82: =AVERAGEIF($B$2:$B$247,2019,$M$2:$M$247) -> 2.9876404
A83: O | B83: 2020 | C83: =DATE(B83,D83,1) -> 43952 | D83: 5 | E83: 1491 | F83: 13 | G83: =E83-F83 -> 1478 | H83: 3595 | I83: 0.7093 | J83: 9164 | K83: 0.0013425926 | L83: =J83/H83 -> 2.549096 | M83: 0.14 | N83: 5 | O83: 1139 | P83: 14 | Q83: =(G83/E83)*100 -> 99.128102 | R83: =O83/E83 -> 0.76391683 | S83: =O83/H83 -> 0.31682893 | T83: =O83/N83 -> 227.8 | U83: =1/M83 -> 7.1428571
A84: P | B84: 2020 | C84: =DATE(B84,D84,1) -> 43983 | D84: 6 | E84: 3114 | F84: 2655 | G84: =E84-F84 -> 459 | H84: 3457 | I84: 0.6312 | J84: 8551 | K84: 0.0011805556 | L84: =J84/H84 -> 2.473532 | M84: 0.58 | N84: 20 | O84: 2666 | P84: 26 | Q84: =(G84/E84)*100 -> 14.739884 | R84: =O84/E84 -> 0.85613359 | S84: =O84/H84 -> 0.77118889 | T84: =O84/N84 -> 133.3 | U84: =1/M84 -> 1.7241379
A85: P | B85: 2020 | C85: =DATE(B85,D85,1) -> 44013 | D85: 7 | E85: 2997 | F85: 2602 | G85: =E85-F85 -> 395 | H85: 3368 | I85: 0.6434 | J85: 7758 | K85: 0.001087963 | L85: =J85/H85 -> 2.3034442 | M85: 0.24 | N85: 8 | O85: 1059 | P85: 10 | Q85: =(G85/E85)*100 -> 13.179847 | R85: =O85/E85 -> 0.35335335 | S85: =O85/H85 -> 0.31442993 | T85: =O85/N85 -> 132.375 | U85: =1/M85 -> 4.1666667
A86: M | B86: 2019 | C86: =DATE(B86,D86,1) -> 43770 | D86: 11 | E86: 2251 | F86: 1262 | G86: =E86-F86 -> 989 | H86: 3265 | I86: 0.5023 | J86: 12367 | K86: 0.001712963 | L86: =J86/H86 -> 3.7877489 | M86: 0.12 | N86: 4 | O86: 644 | P86: 8 | Q86: =(G86/E86)*100 -> 43.936028 | R86: =O86/E86 -> 0.28609507 | S86: =O86/H86 -> 0.19724349 | T86: =O86/N86 -> 161 | U86: =1/M86 -> 8.3333333
A87: P | B87: 2020 | C87: =DATE(B87,D87,1) -> 43952 | D87: 5 | E87: 2773 | F87: 2289 | G87: =E87-F87 -> 484 | H87: 3189 | I87: 0.6394 | J87: 8462 | K87: 0.0013888889 | L87: =J87/H87 -> 2.6534964 | M87: 0.44 | N87: 14 | O87: 2382 | P87: 28 | Q87: =(G87/E87)*100 -> 17.454021 | R87: =O87/E87 -> 0.85899748 | S87: =O87/H87 -> 0.74694262 | T87: =O87/N87 -> 170.14286 | U87: =1/M87 -> 2.2727273
A88: C | B88: 2019 | C88: =DATE(B88,D88,1) -> 43709 | D88: 9 | E88: 2805 | F88: 2243 | G88: =E88-F88 -> 562 | H88: 3121 | I88: 0.4998 | J88: 11136 | K88: 0.0012152778 | L88: =J88/H88 -> 3.5680872 | M88: 0.13 | N88: 4 | O88: 1132 | P88: 9 | Q88: =(G88/E88)*100 -> 20.035651 | R88: =O88/E88 -> 0.40356506 | S88: =O88/H88 -> 0.36270426 | T88: =O88/N88 -> 283 | U88: =1/M88 -> 7.6923077
A89: P | B89: 2020 | C89: =DATE(B89,D89,1) -> 43831 | D89: 1 | E89: 2688 | F89: 2089 | G89: =E89-F89 -> 599 | H89: 2978 | I89: 0.7398 | J89: 5905 | K89: 0.0009375 | L89: =J89/H89 -> 1.9828744 | M89: 0.34 | N89: 10 | O89: 2262 | P89: 22 | Q89: =(G89/E89)*100 -> 22.284226 | R89: =O89/E89 -> 0.84151786 | S89: =O89/H89 -> 0.75957018 | T89: =O89/N89 -> 226.2 | U89: =1/M89 -> 2.9411765
A90: R | B90: 2019 | C90: =DATE(B90,D90,1) -> 43739 | D90: 10 | E90: 2033 | F90: 1523 | G90: =E90-F90 -> 510 | H90: 2840 | I90: 0.3711 | J90: 11116 | K90: 0.0020138889 | L90: =J90/H90 -> 3.9140845 | M90: 0.25 | N90: 7 | O90: 1280 | P90: 12 | Q90: =(G90/E90)*100 -> 25.08608 | R90: =O90/E90 -> 0.62961141 | S90: =O90/H90 -> 0.45070423 | T90: =O90/N90 -> 182.85714 | U90: =1/M90 -> 4
A91: I | B91: 2020 | C91: =DATE(B91,D91,1) -> 43922 | D91: 4 | E91: 2537 | F91: 1834 | G91: =E91-F91 -> 703 | H91: 2797 | I91: 0.5981 | J91: 12348 | K91: 0.0017013889 | L91: =J91/H91 -> 4.4147301 | M91: 1.32 | N91: 37 | O91: 4221 | P91: 56 | Q91: =(G91/E91)*100 -> 27.709894 | R91: =O91/E91 -> 1.6637761 | S91: =O91/H91 -> 1.5091169 | T91: =O91/N91 -> 114.08108 | U91: =1/M91 -> 0.75757576
A92: R | B92: 2019 | C92: =DATE(B92,D92,1) -> 43800 | D92: 12 | E92: 2045 | F92: 1495 | G92: =E92-F92 -> 550 | H92: 2777 | I92: 0.5124 | J92: 10627 | K92: 0.0015509259 | L92: =J92/H92 -> 3.8267915 | M92: 0.11 | N92: 3 | O92: 333 | P92: 5 | Q92: =(G92/E92)*100 -> 26.894866 | R92: =O92/E92 -> 0.16283619 | S92: =O92/H92 -> 0.11991358 | T92: =O92/N92 -> 111 | U92: =1/M92 -> 9.0909091
A93: M | B93: 2019 | C93: =DATE(B93,D93,1) -> 43800 | D93: 12 | E93: 2202 | F93: 1439 | G93: =E93-F93 -> 763 | H93: 2714 | I93: 0.5247 | J93: 8588 | K93: 0.001412037 | L93: =J93/H93 -> 3.1643331 | M93: 0.26 | N93: 7 | O93: 1242 | P93: 12 | Q93: =(G93/E93)*100 -> 34.650318 | R93: =O93/E93 -> 0.5640327 | S93: =O93/H93 -> 0.45762712 | T93: =O93/N93 -> 177.42857 | U93: =1/M93 -> 3.8461538
A94: P | B94: 2020 | C94: =DATE(B94,D94,1) -> 43862 | D94: 2 | E94: 2355 | F94: 1800 | G94: =E94-F94 -> 555 | H94: 2637 | I94: 0.73 | J94: 5229 | K94: 0.00094907407 | L94: =J94/H94 -> 1.9829352 | M94: 0.42 | N94: 11 | O94: 1863 | P94: 17 | Q94: =(G94/E94)*100 -> 23.566879 | R94: =O94/E94 -> 0.7910828 | S94: =O94/H94 -> 0.70648464 | T94: =O94/N94 -> 169.36364 | U94: =1/M94 -> 2.3809524
... A98: O | B98: 2020 | C98: =DATE(B98,D98,1) -> 44013 | D98: 7 | E98: 946 | F98: 20 | G98: =E98-F98 -> 926 | H98: 2424 | I98: 0.7459 | J98: 5082 | K98: 0.0012152778 | L98: =J98/H98 -> 2.0965347 | M98: 0.12 | N98: 3 | O98: 277 | P98: 7 | Q98: =(G98/E98)*100 -> 97.885835 | R98: =O98/E98 -> 0.29281184 | S98: =O98/H98 -> 0.11427393 | T98: =O98/N98 -> 92.333333 | U98: =1/M98 -> 8.3333333
A99: D | B99: 2020 | C99: =DATE(B99,D99,1) -> 43922 | D99: 4 | E99: 1965 | F99: 1886 | G99: =E99-F99 -> 79 | H99: 2317 | I99: 0.8325 | J99: 3173 | K99: 0.00046296296 | L99: =J99/H99 -> 1.3694432 | M99: 0 | N99: 0 | O99: 0 | P99: 0 | Q99: =(G99/E99)*100 -> 4.0203562 | R99: =O99/E99 -> 0 | S99: =O99/H99 -> 0 | T99: =O99/N99 -> #DIV/0! | U99: =1/M99 -> #DIV/0! | V99: =SUMIF(B99:B344,2019,F99:F344) -> 14345 | W99: =AVERAGEIF($B$2:$B$247,2019,$M$2:$M$247) -> 2.9876404
A100: R | B100: 2020 | C100: =DATE(B100,D100,1) -> 43862 | D100: 2 | E100: 1682 | F100: 1212 | G100: =E100-F100 -> 470 | H100: 2274 | I100: 0.4982 | J100: 9928 | K100: 0.0025347222 | L100: =J100/H100 -> 4.3658751 | M100: 0.48 | N100: 11 | O100: 2198 | P100: 23 | Q100: =(G100/E100)*100 -> 27.942925 | R100: =O100/E100 -> 1.3067776 | S100: =O100/H100 -> 0.96657872 | T100: =O100/N100 -> 199.81818 | U100: =1/M100 -> 2.0833333
A101: N | B101: 2020 | C101: =DATE(B101,D101,1) -> 43922 | D101: 4 | E101: 2091 | F101: 2072 | G101: =E101-F101 -> 19 | H101: 2235 | I101: 0.8568 | J101: 3321 | K101: 0.00030092593 | L101: =J101/H101 -> 1.485906 | M101: 0 | N101: 0 | O101: 0 | P101: 0 | Q101: =(G101/E101)*100 -> 0.90865615 | R101: =O101/E101 -> 0 | S101: =O101/H101 -> 0 | T101: =O101/N101 -> #DIV/0! | U101: =1/M101 -> #DIV/0! | V101: =SUMIF(B101:B346,2019,F101:F346) -> 14345 | W101: =AVERAGEIF($B$2:$B$247,2019,$M$2:$M$247) -> 2.9876404
A102: P | B102: 2019 | C102: =DATE(B102,D102,1) -> 43800 | D102: 12 | E102: 1944 | F102: 1528 | G102: =E102-F102 -> 416 | H102: 2164 | I102: 0.7089 | J102: 4480 | K102: 0.00086805556 | L102: =J102/H102 -> 2.0702403 | M102: 0.23 | N102: 5 | O102: 644 | P102: 5 | Q102: =(G102/E102)*100 -> 21.399177 | R102: =O102/E102 -> 0.33127572 | S102: =O102/H102 -> 0.29759704 | T102: =O102/N102 -> 128.8 | U102: =1/M102 -> 4.3478261
A103: M | B103: 2020 | C103: =DATE(B103,D103,1) -> 43952 | D103: 5 | E103: 1724 | F103: 1011 | G103: =E103-F103 -> 713 | H103: 2089 | I103: 0.5615 | J103: 8703 | K103: 0.0019212963 | L103: =J103/H103 -> 4.1661082 | M103: 1.29 | N103: 27 | O103: 3759 | P103: 43 | Q103: =(G103/E103)*100 -> 41.357309 | R103: =O103/E103 -> 2.1803944 | S103: =O103/H103 -> 1.7994256 | T103: =O103/N103 -> 139.22222 | U103: =1/M103 -> 0.7751938
...

Sheet Pivot Table
G1: KPI | M1: 1049791 | N1: 4659 | O1: 970399
M2: 1669520 | N2: 16602 | O2: 2722505
A3: Year | B3: Sum of Users | D3: Year | E3: Sum of Users | M3: 2719311 | N3: 21261 | O3: 3692904
A4: 2019 | B4: 1049791 | D4: Jan | E4: 225887
A5: 2020 | B5: 1669520 | D5: Feb | E5: 208961 | G5: Source | H5: Sum of Pageviews
D6: Mar | E6: 179824 | G6: A | H6: 4246914
D7: Apr | E7: 193983 | G7: B | H7: 2640848
D8: May | E8: 314610 | G8: C | H8: 1138068 | J8: Year | K8: Sum of Users | L8: Sum of Transactions
D9: Jun | E9: 228555 | G9: D | H9: 5161 | J9: 2019 | K9: 1049791 | L9: 4659 | V9: Month | W9: =T10 -> Average of Revenue Per Session | Z9: =U10 -> 0 | AA9: =V10 -> Jan
D10: Jul | E10: 198341 | G10: E | H10: 901834 | J10: 2020 | K10: 1669520 | L10: 16602 | N10: Year | O10: Sum of Revenue | Q10: Source | R10: Average of Bounce Rate | S10: Average of Conversion Rate (%) | T10: Average of Revenue Per Session | V10: =Q11 -> Jan | W10: =T11 -> 8.1062085
D11: Aug | E11: 119359 | G11: F | H11: 504529 | J11: Grand Total | K11: 2719311 | L11: 21261 | N11: 2019 | Q11: Jan | R11: 0.5381 | S11: 3.0704545 | T11: 8.1062085 | V11: =Q12 -> Feb | W11: =T12 -> 6.9211405
D12: Sep | E12: 217509 | G12: G | H12: 253387 | N12: Sep | O12: 155796 | Q12: Feb | R12: 0.512935 | S12: 3.4805 | T12: 6.9211405 | V12: =Q13 -> Mar | W12: =T13 -> 6.1898516
D13: Oct | E13: 280312 | G13: H | H13: 236384 | N13: Oct | O13: 283905 | Q13: Mar | R13: 0.53354444 | S13: 3.5933333 | T13: 6.1898516 | V13: =Q14 -> Apr | W13: =T14 -> 6.4131779
D14: Nov | E14: 288385 | G14: I | H14: 275471 | J14: Year | K14: Sum of Users | L14: Sum of Revenue | N14: Nov | O14: 270010 | Q14: Apr | R14: 0.54559524 | S14: 3.7185714 | T14: 6.4131779 | V14: =Q15 -> May | W14: =T15 -> 4.7547896
D15: Dec | E15: 263585 | G15: J | H15: 29756 | J15: 2019 | K15: 1049791 | L15: 970399 | N15: Dec | O15: 260688 | Q15: May | R15: 0.48411429 | S15: 2.6810714 | T15: 4.7547896 | V15: =Q16 -> Jun | W15: =T16 -> 7.952433
G16: K | H16: 100691 | J16: 2020 | K16: 1669520 | L16: 2722505 | N16: 2020 | Q16: Jun | R16: 0.50171176 | S16: 4.2829412 | T16: 7.952433 | V16: =Q17 -> Jul | W16: =T17 -> 8.841459
G17: L | H17: 48695 | J17: Grand Total | K17: 2719311 | L17: 3692904 | N17: Jan | O17: 307336 | Q17: Jul | R17: 0.52184667 | S17: 4.8833333 | T17: 8.841459 | V17: =Q18 -> Aug | W17: =T18 -> 1.5785186
G18: M | H18: 84781 | N18: Feb | O18: 323540 | Q18: Aug | R18: 0.51984706 | S18: 1.0311765 | T18: 1.5785186 | V18: =Q19 -> Sep | W18: =T19 -> 5.6996407
G19: N | H19: 11048 | N19: Mar | O19: 277426 | Q19: Sep | R19: 0.50873636 | S19: 2.8754545 | T19: 5.6996407 | V19: =Q20 -> Oct | W19: =T20 -> 8.4736341
G20: O | H20: 24051 | N20: Apr | O20: 373345 | Q20: Oct | R20: 0.29653913 | S20: 3.5221739 | T20: 8.4736341 | V20: =Q21 -> Nov | W20: =T21 -> 7.0658579
G21: P | H21: 57375 | N21: May | O21: 589545 | Q21: Nov | R21: 0.46848636 | S21: 2.6613636 | T21: 7.0658579 | V21: =Q22 -> Dec | W21: =T22 -> 5.7635374
G22: R | H22: 75710 | J22: YOY Metrics | N22: Jun | O22: 469360 | Q22: Dec | R22: 0.47541818 | S22: 2.8672727 | T22: 5.7635374
G23: S | H23: 37578 | N23: Jul | O23: 266165
G24: T | H24: 29809 | J24: Users Growth | L24: =((M2-M1)/M3) -> 0.22789927 | N24: Aug | O24: 115788
G25: U | H25: 13857
G26: V | H26: 6931 | J26: Revenue YOY | L26: =((O2-O1)/O3) -> 0.47445208
G27: Y | H27: 2576
G28: Z | H28: 28758 | J28: Tranasactions YOY | L28: =((N2-N1)/N3) -> 0.56173275
J30: Conversion rate | L30: =((GETPIVOTDATA("[Measures].[Sum of Average Conversion Rate in 2020]",$M$32)-GETPIVOTDATA("[Measures].[Sum of Average Conversion rate 2019]",$O$32))/GETPIVOTDATA("[Measures].[Max of Conversion Rate (%)]",$N$36))*100 -> 0.74971618
M32: Sum of Average Conversion Rate in 2020 | O32: Sum of Average Conversion rate 2019
M33: 3.303121 | O33: 2.9876404
D35: Source | E35: Sum of Bounce Rate | F35: Sum of Conversion Rate (%) | H35: Month | I35: =E35 -> Sum of Bounce Rate | J35: =F35 -> Sum of Conversion Rate (%)
D36: Jan | E36: 11.8382 | F36: 67.55 | H36: =D36 -> Jan | I36: =E36 -> 11.8382 | J36: =F36 -> 67.55 | N36: Max of Conversion Rate (%)
D37: Feb | E37: 10.2587 | F37: 69.61 | H37: =D37 -> Feb | I37: =E37 -> 10.2587 | J37: =F37 -> 69.61 | N37: 42.08
D38: Mar | E38: 9.6038 | F38: 64.68 | H38: =D38 -> Mar | I38: =E38 -> 9.6038 | J38: =F38 -> 64.68
D39: Apr | E39: 11.4575 | F39: 78.09 | H39: =D39 -> Apr | I39: =E39 -> 11.4575 | J39: =F39 -> 78.09
D40: May | E40: 13.5552 | F40: 75.07 | H40: =D40 -> May | I40: =E40 -> 13.5552 | J40: =F40 -> 75.07
D41: Jun | E41: 8.5291 | F41: 72.81 | H41: =D41 -> Jun | I41: =E41 -> 8.5291 | J41: =F41 -> 72.81
D42: Jul | E42: 7.8277 | F42: 73.25 | H42: =D42 -> Jul | I42: =E42 -> 7.8277 | J42: =F42 -> 73.25
D43: Aug | E43: 8.8374 | F43: 17.53 | H43: =D43 -> Aug | I43: =E43 -> 8.8374 | J43: =F43 -> 17.53 | M43: Source | N43: Average of Pageviews | P43: Source | Q43: Sum of Revenue | R43: Sum of Quantity Sold | T43: Month | U43: =Q43 -> Sum of Revenue | V43: =R43 -> Sum of Quantity Sold
...

Sheet Dashboard
B2: ='Pivot Table'!H86 -> 2719311 | C2: ='Pivot Table'!I86 -> 635753 | D2: ='Pivot Table'!J86 -> 2083558 | E2: ='Pivot Table'!M86 -> 11.593514 | F2: ='Pivot Table'!L86 -> 14951.028 | G2: ='Pivot Table'!N86 -> 6.4500729 | H2: =GETPIVOTDATA("[Measures].[Max of Conversion Rate (%)]",'Pivot Table'!$R$81) -> 42.08
B4: Total Users | C4: Returning Users | D4: Total Transactions | E4: Avg. Revenue Per User | F4: Total Revenue | G4: Avg. Revenue Per Session | H4: Max Conversion Rate %
N7: %%%
M8: ='Pivot Table'!L28 -> 0.56173275
T18: =
